<?xml version='1.0'?>
<sdf version='1.4'>
  <model name="JetBot">
    <static>false</static>

    <link name='chassis'>
      <pose>0.0 0.0 0.043 1.57079632679 0.0 1.57079632679</pose>
      <inertial>
        <mass>10.0</mass>
        <pose>0.0 -0.01 -0.02 0.0 0.0 0.0</pose>
      </inertial>
      <!-- <collision name='collision'> -->
      <!--   <geometry> -->
      <!--     <mesh> -->
      <!--       <scale>0.001 0.001 0.001</scale> -->
      <!--       <uri>model://jetbot/meshes/JetBot-v3-Chassis.dae</uri> -->
      <!--     </mesh> -->
      <!--   </geometry> -->
      <!-- </collision> -->

      <visual name='visual'>
        <geometry>
          <mesh>
            <scale>0.001 0.001 0.001</scale>
            <uri>model://jetbot/meshes/JetBot-v3-Chassis.dae</uri>
          </mesh>
        </geometry>
      </visual>
    </link>

    <link name='caster'>
      <pose>-0.05 0 0.0127 0 0 0</pose>
      <inertial>
        <mass>10.0</mass>
      </inertial>
      <collision name='collision'>
        <geometry>
          <sphere>
            <radius>0.0127</radius>
          </sphere>
        </geometry>
      </collision>
      <visual name='visual'>
        <geometry>
          <sphere>
            <radius>0.0127</radius>
          </sphere>
        </geometry>
      </visual>
    </link>

    <link name="left_wheel">
      <pose>0.03 0.05125 0.03 0.0 0.0 1.57079632679</pose>
      <inertial>
        <mass>2.0</mass>
      </inertial>
      <collision name="collision">
        <geometry>
          <mesh>
            <scale>0.001 0.001 0.001</scale>
            <uri>model://jetbot/meshes/JetBot-v3-Wheel.stl</uri>
          </mesh>
        </geometry>
        <surface>
          <friction>
            <ode>
              <mu>10.0</mu>
              <mu2>10.0</mu2>
            </ode>
          </friction>
        </surface>
      </collision>
      <visual name="visual">
        <geometry>
          <mesh>
            <scale>0.001 0.001 0.001</scale>
            <uri>model://jetbot/meshes/JetBot-v3-Wheel.stl</uri>
          </mesh>
        </geometry>
        <material>
          <ambient>0.1 0.1 0.1 1</ambient>
          <diffuse>0.1 0.1 0.1 1</diffuse>
          <specular>0 0 0 0</specular>
          <emissive>0 0 0 1</emissive>
        </material>
      </visual>
    </link>

    <link name="right_wheel">
      <pose>0.03 -0.0595 0.03 0.0 0.0 1.57079632679</pose>
      <inertial>
        <mass>2.0</mass>
      </inertial>
      <collision name="collision">
        <geometry>
          <mesh>
            <scale>0.001 0.001 0.001</scale>
            <uri>model://jetbot/meshes/JetBot-v3-Wheel.stl</uri>
          </mesh>
        </geometry>
        <surface>
          <friction>
            <ode>
              <mu>10.0</mu>
              <mu2>10.0</mu2>
            </ode>
          </friction>
        </surface>
      </collision>
      <visual name="visual">
        <geometry>
          <mesh>
            <scale>0.001 0.001 0.001</scale>
            <uri>model://jetbot/meshes/JetBot-v3-Wheel.stl</uri>
          </mesh>
        </geometry>
        <material>
          <ambient>0.1 0.1 0.1 1</ambient>
          <diffuse>0.1 0.1 0.1 1</diffuse>
          <specular>0 0 0 0</specular>
          <emissive>0 0 0 1</emissive>
        </material>
      </visual>
    </link>

    <joint name='caster_joint' type='fixed'>
      <pose>0.03 0 0.0127 0 0 0</pose>
      <child>caster</child>
      <parent>chassis</parent>
    </joint>

    <joint type="revolute" name="left_wheel_hinge">
      <pose>0 0 0 0 0 0</pose>
      <child>left_wheel</child>
      <parent>chassis</parent>
      <axis>
        <xyz>0 1 0</xyz>
        <dynamics>
          <damping>1.0</damping>
        </dynamics>
      </axis>
    </joint>

    <joint type="revolute" name="right_wheel_hinge">
      <pose>0 0 0 0 0 0</pose>
      <child>right_wheel</child>
      <parent>chassis</parent>
      <axis>
        <xyz>0 1 0</xyz>
        <dynamics>
          <damping>1.0</damping>
        </dynamics>
      </axis>
    </joint>

    <link name="camera_link">
      <gravity>false</gravity>
      <pose>0.055 0.0 0.0857 0 0.25 0</pose>
      <inertial>
        <mass>0.01</mass>
      </inertial>
      <visual name="visual">
        <geometry>
          <box>
            <size>0.001 0.001 0.001</size>
          </box>
        </geometry>
      </visual>
      <sensor name="camera" type="camera">
        <camera>
          <horizontal_fov>2.79253</horizontal_fov>
          <image>
            <width>640</width>
            <height>480</height>
          </image>
          <clip>
            <near>0.01</near>
            <far>1</far>
          </clip>
        </camera>
        <always_on>1</always_on>
        <update_rate>10</update_rate>
        <visualize>true</visualize>
        <topic>/image_raw</topic>
        <gz_frame_id>camera_link</gz_frame_id>
        <plugin name="gz::sim::systems::Sensors"
          filename="libgz-sim-sensors-system.so">
          <render_engine>ogre2</render_engine>
          <gz_frame_id>camera_link</gz_frame_id>
        </plugin>
      </sensor>
    </link>

    <joint name="camera_joint" type="revolute">
      <parent>chassis</parent>
      <child>camera_link</child>
      <pose>0.0 0.0 0.0 0.0 0.0 0.0</pose>
      <axis>
        <xyz>0.1 0.0 0.0</xyz>
      </axis>
    </joint>

    <plugin
      filename='libgz-sim-diff-drive-system.so'
      name='gz::sim::systems::DiffDrive'>
      <left_joint>left_wheel_hinge</left_joint>
      <right_joint>right_wheel_hinge</right_joint>
      <wheel_separation>0.9398</wheel_separation>
      <wheel_radius>0.03</wheel_radius>
      <max_linear_acceleration>0.1</max_linear_acceleration>
      <min_linear_acceleration>-0.1</min_linear_acceleration>
      <max_angular_acceleration>0.2</max_angular_acceleration>
      <min_angular_acceleration>-0.2</min_angular_acceleration>
      <odom_publish_frequency>50</odom_publish_frequency>
      <topic>cmd_vel</topic>
      <frame_id>odom</frame_id>
      <child_frame_id>chassis</child_frame_id>
    </plugin>

  </model>
</sdf>
